Workbook

Sheet data
A1: year | B1: foreign_tariffrt_weighted
A2: 1840 | B2: =tau!AD3 -> 23.099235
A3: 1841 | B3: =tau!AD4 -> 24.34394
A4: 1842 | B4: =tau!AD5 -> 26.078701
A5: 1843 | B5: =tau!AD6 -> 28.118667
A6: 1844 | B6: =tau!AD7 -> 27.161691
A7: 1845 | B7: =tau!AD8 -> 25.547338
A8: 1846 | B8: =tau!AD9 -> 21.518954
A9: 1847 | B9: =tau!AD10 -> 19.192781
A10: 1848 | B10: =tau!AD11 -> 19.875708
A11: 1849 | B11: =tau!AD12 -> 19.926468
A12: 1850 | B12: =tau!AD13 -> 18.798659
A13: 1851 | B13: =tau!AD14 -> 18.645183
... A186: 2024 | B186: =tau!AD187 -> 0.80836768

Sheet tau
A1: Raw tau | P1: Weighted tau
A2: year | B2: GBR | C2: FRA | D2: DEU | E2: ITA | F2: CAN | G2: CHE | H2: BEL | I2: NLD | J2: PRT | K2: ESP | L2: JPN | M2: MEX | N2: BRA | P2: year | Q2: GBR | R2: FRA | S2: DEU | T2: ITA | U2: CAN | V2: CHE | W2: BEL | X2: NLD | Y2: PRT | Z2: ESP | AA2: JPN | AB2: MEX | AC2: BRA | AD2: Sum
A3: 1840 | B3: =IF(identifiers!B3=1,GBR!E3,"") -> 24.988867 | C3: =IF(identifiers!C3=1,FRA!F3,"") -> 17.8982 | D3: =IF(identifiers!D3=1,DEU!E3,"") | E3: =IF(identifiers!E3=1,ITA!E3,"") | F3: =IF(identifiers!F3=1,CAN!E3,"") | G3: =IF(identifiers!G3=1,CHE!E3,"") | H3: =IF(identifiers!H3=1,BEL!E3,"") | I3: =IF(identifiers!I3=1,NLD!E3,"") | J3: =IF(identifiers!J3=1,PRT!E3,"") | K3: =IF(identifiers!K3=1,ESP!E3,"") | L3: =IF(identifiers!L3=1,JPN!E3,"") | M3: =IF(identifiers!M3=1,MEX!E3,"") | N3: =IF(identifiers!N3=1,BRA!E3,"") | P3: 1840 | Q3: =IF(ISNUMBER(B3*export_shares!R3),B3*export_shares!R3,"") -> 18.329441 | R3: =IF(ISNUMBER(C3*export_shares!S3),C3*export_shares!S3,"") -> 4.7697932 | S3: =IF(ISNUMBER(D3*export_shares!T3),D3*export_shares!T3,"") | T3: =IF(ISNUMBER(E3*export_shares!U3),E3*export_shares!U3,"") | U3: =IF(ISNUMBER(F3*export_shares!V3),F3*export_shares!V3,"") | V3: =IF(ISNUMBER(G3*export_shares!W3),G3*export_shares!W3,"") | W3: =IF(ISNUMBER(H3*export_shares!X3),H3*export_shares!X3,"") | X3: =IF(ISNUMBER(I3*export_shares!Y3),I3*export_shares!Y3,"") | ... AC3: =IF(ISNUMBER(N3*export_shares!AD3),N3*export_shares!AD3,"") | AD3: =SUM(Q3:AC3) -> 23.099235
A4: 1841 | B4: =IF(identifiers!B4=1,GBR!E4,"") -> 26.810364 | C4: =IF(identifiers!C4=1,FRA!F4,"") -> 17.8982 | D4: =IF(identifiers!D4=1,DEU!E4,"") | E4: =IF(identifiers!E4=1,ITA!E4,"") | F4: =IF(identifiers!F4=1,CAN!E4,"") | G4: =IF(identifiers!G4=1,CHE!E4,"") | H4: =IF(identifiers!H4=1,BEL!E4,"") | I4: =IF(identifiers!I4=1,NLD!E4,"") | J4: =IF(identifiers!J4=1,PRT!E4,"") | K4: =IF(identifiers!K4=1,ESP!E4,"") | L4: =IF(identifiers!L4=1,JPN!E4,"") | M4: =IF(identifiers!M4=1,MEX!E4,"") | N4: =IF(identifiers!N4=1,BRA!E4,"") | P4: 1841 | Q4: =IF(ISNUMBER(B4*export_shares!R4),B4*export_shares!R4,"") -> 19.390649 | R4: =IF(ISNUMBER(C4*export_shares!S4),C4*export_shares!S4,"") -> 4.9532912 | S4: =IF(ISNUMBER(D4*export_shares!T4),D4*export_shares!T4,"") | T4: =IF(ISNUMBER(E4*export_shares!U4),E4*export_shares!U4,"") | U4: =IF(ISNUMBER(F4*export_shares!V4),F4*export_shares!V4,"") | V4: =IF(ISNUMBER(G4*export_shares!W4),G4*export_shares!W4,"") | W4: =IF(ISNUMBER(H4*export_shares!X4),H4*export_shares!X4,"") | X4: =IF(ISNUMBER(I4*export_shares!Y4),I4*export_shares!Y4,"") | ... AC4: =IF(ISNUMBER(N4*export_shares!AD4),N4*export_shares!AD4,"") | AD4: =SUM(Q4:AC4) -> 24.34394
A5: 1842 | B5: =IF(identifiers!B5=1,GBR!E5,"") -> 29.552366 | C5: =IF(identifiers!C5=1,FRA!F5,"") -> 17.898219 | D5: =IF(identifiers!D5=1,DEU!E5,"") | E5: =IF(identifiers!E5=1,ITA!E5,"") | F5: =IF(identifiers!F5=1,CAN!E5,"") | G5: =IF(identifiers!G5=1,CHE!E5,"") | H5: =IF(identifiers!H5=1,BEL!E5,"") | I5: =IF(identifiers!I5=1,NLD!E5,"") | J5: =IF(identifiers!J5=1,PRT!E5,"") | K5: =IF(identifiers!K5=1,ESP!E5,"") | L5: =IF(identifiers!L5=1,JPN!E5,"") | M5: =IF(identifiers!M5=1,MEX!E5,"") | N5: =IF(identifiers!N5=1,BRA!E5,"") | P5: 1842 | Q5: =IF(ISNUMBER(B5*export_shares!R5),B5*export_shares!R5,"") -> 20.74391 | R5: =IF(ISNUMBER(C5*export_shares!S5),C5*export_shares!S5,"") -> 5.33479 | S5: =IF(ISNUMBER(D5*export_shares!T5),D5*export_shares!T5,"") | T5: =IF(ISNUMBER(E5*export_shares!U5),E5*export_shares!U5,"") | U5: =IF(ISNUMBER(F5*export_shares!V5),F5*export_shares!V5,"") | V5: =IF(ISNUMBER(G5*export_shares!W5),G5*export_shares!W5,"") | W5: =IF(ISNUMBER(H5*export_shares!X5),H5*export_shares!X5,"") | X5: =IF(ISNUMBER(I5*export_shares!Y5),I5*export_shares!Y5,"") | ... AC5: =IF(ISNUMBER(N5*export_shares!AD5),N5*export_shares!AD5,"") | AD5: =SUM(Q5:AC5) -> 26.078701
A6: 1843 | B6: =IF(identifiers!B6=1,GBR!E6,"") -> 31.120124 | C6: =IF(identifiers!C6=1,FRA!F6,"") -> 17.854714 | D6: =IF(identifiers!D6=1,DEU!E6,"") | E6: =IF(identifiers!E6=1,ITA!E6,"") | F6: =IF(identifiers!F6=1,CAN!E6,"") | G6: =IF(identifiers!G6=1,CHE!E6,"") | H6: =IF(identifiers!H6=1,BEL!E6,"") | I6: =IF(identifiers!I6=1,NLD!E6,"") | J6: =IF(identifiers!J6=1,PRT!E6,"") | K6: =IF(identifiers!K6=1,ESP!E6,"") | L6: =IF(identifiers!L6=1,JPN!E6,"") | M6: =IF(identifiers!M6=1,MEX!E6,"") | N6: =IF(identifiers!N6=1,BRA!E6,"") | P6: 1843 | Q6: =IF(ISNUMBER(B6*export_shares!R6),B6*export_shares!R6,"") -> 24.078824 | R6: =IF(ISNUMBER(C6*export_shares!S6),C6*export_shares!S6,"") -> 4.0398427 | S6: =IF(ISNUMBER(D6*export_shares!T6),D6*export_shares!T6,"") | T6: =IF(ISNUMBER(E6*export_shares!U6),E6*export_shares!U6,"") | U6: =IF(ISNUMBER(F6*export_shares!V6),F6*export_shares!V6,"") | V6: =IF(ISNUMBER(G6*export_shares!W6),G6*export_shares!W6,"") | W6: =IF(ISNUMBER(H6*export_shares!X6),H6*export_shares!X6,"") | X6: =IF(ISNUMBER(I6*export_shares!Y6),I6*export_shares!Y6,"") | ... AC6: =IF(ISNUMBER(N6*export_shares!AD6),N6*export_shares!AD6,"") | AD6: =SUM(Q6:AC6) -> 28.118667
A7: 1844 | B7: =IF(identifiers!B7=1,GBR!E7,"") -> 29.617214 | C7: =IF(identifiers!C7=1,FRA!F7,"") -> 17.898163 | D7: =IF(identifiers!D7=1,DEU!E7,"") | E7: =IF(identifiers!E7=1,ITA!E7,"") | F7: =IF(identifiers!F7=1,CAN!E7,"") | G7: =IF(identifiers!G7=1,CHE!E7,"") | H7: =IF(identifiers!H7=1,BEL!E7,"") | I7: =IF(identifiers!I7=1,NLD!E7,"") | J7: =IF(identifiers!J7=1,PRT!E7,"") | K7: =IF(identifiers!K7=1,ESP!E7,"") | L7: =IF(identifiers!L7=1,JPN!E7,"") | M7: =IF(identifiers!M7=1,MEX!E7,"") | N7: =IF(identifiers!N7=1,BRA!E7,"") | P7: 1844 | Q7: =IF(ISNUMBER(B7*export_shares!R7),B7*export_shares!R7,"") -> 23.411444 | R7: =IF(ISNUMBER(C7*export_shares!S7),C7*export_shares!S7,"") -> 3.7502476 | S7: =IF(ISNUMBER(D7*export_shares!T7),D7*export_shares!T7,"") | T7: =IF(ISNUMBER(E7*export_shares!U7),E7*export_shares!U7,"") | U7: =IF(ISNUMBER(F7*export_shares!V7),F7*export_shares!V7,"") | V7: =IF(ISNUMBER(G7*export_shares!W7),G7*export_shares!W7,"") | W7: =IF(ISNUMBER(H7*export_shares!X7),H7*export_shares!X7,"") | X7: =IF(ISNUMBER(I7*export_shares!Y7),I7*export_shares!Y7,"") | ... AC7: =IF(ISNUMBER(N7*export_shares!AD7),N7*export_shares!AD7,"") | AD7: =SUM(Q7:AC7) -> 27.161691
A8: 1845 | B8: =IF(identifiers!B8=1,GBR!E8,"") -> 27.585237 | C8: =IF(identifiers!C8=1,FRA!F8,"") -> 17.898529 | D8: =IF(identifiers!D8=1,DEU!E8,"") | E8: =IF(identifiers!E8=1,ITA!E8,"") | F8: =IF(identifiers!F8=1,CAN!E8,"") | G8: =IF(identifiers!G8=1,CHE!E8,"") | H8: =IF(identifiers!H8=1,BEL!E8,"") | I8: =IF(identifiers!I8=1,NLD!E8,"") | J8: =IF(identifiers!J8=1,PRT!E8,"") | K8: =IF(identifiers!K8=1,ESP!E8,"") | L8: =IF(identifiers!L8=1,JPN!E8,"") | M8: =IF(identifiers!M8=1,MEX!E8,"") | N8: =IF(identifiers!N8=1,BRA!E8,"") | P8: 1845 | Q8: =IF(ISNUMBER(B8*export_shares!R8),B8*export_shares!R8,"") -> 21.781827 | R8: =IF(ISNUMBER(C8*export_shares!S8),C8*export_shares!S8,"") -> 3.7655107 | S8: =IF(ISNUMBER(D8*export_shares!T8),D8*export_shares!T8,"") | T8: =IF(ISNUMBER(E8*export_shares!U8),E8*export_shares!U8,"") | U8: =IF(ISNUMBER(F8*export_shares!V8),F8*export_shares!V8,"") | V8: =IF(ISNUMBER(G8*export_shares!W8),G8*export_shares!W8,"") | W8: =IF(ISNUMBER(H8*export_shares!X8),H8*export_shares!X8,"") | X8: =IF(ISNUMBER(I8*export_shares!Y8),I8*export_shares!Y8,"") | ... AC8: =IF(ISNUMBER(N8*export_shares!AD8),N8*export_shares!AD8,"") | AD8: =SUM(Q8:AC8) -> 25.547338
A9: 1846 | B9: =IF(identifiers!B9=1,GBR!E9,"") -> 25.79171 | C9: =IF(identifiers!C9=1,FRA!F9,"") -> 17.673256 | D9: =IF(identifiers!D9=1,DEU!E9,"") | E9: =IF(identifiers!E9=1,ITA!E9,"") | F9: =IF(identifiers!F9=1,CAN!E9,"") | G9: =IF(identifiers!G9=1,CHE!E9,"") | H9: =IF(identifiers!H9=1,BEL!E9,"") -> 5.0691244 | I9: =IF(identifiers!I9=1,NLD!E9,"") -> 3.556188 | J9: =IF(identifiers!J9=1,PRT!E9,"") | K9: =IF(identifiers!K9=1,ESP!E9,"") | L9: =IF(identifiers!L9=1,JPN!E9,"") | M9: =IF(identifiers!M9=1,MEX!E9,"") | N9: =IF(identifiers!N9=1,BRA!E9,"") | P9: 1846 | Q9: =IF(ISNUMBER(B9*export_shares!R9),B9*export_shares!R9,"") -> 17.353759 | R9: =IF(ISNUMBER(C9*export_shares!S9),C9*export_shares!S9,"") -> 3.6159332 | S9: =IF(ISNUMBER(D9*export_shares!T9),D9*export_shares!T9,"") | T9: =IF(ISNUMBER(E9*export_shares!U9),E9*export_shares!U9,"") | U9: =IF(ISNUMBER(F9*export_shares!V9),F9*export_shares!V9,"") | V9: =IF(ISNUMBER(G9*export_shares!W9),G9*export_shares!W9,"") | W9: =IF(ISNUMBER(H9*export_shares!X9),H9*export_shares!X9,"") -> 0.38002209 | X9: =IF(ISNUMBER(I9*export_shares!Y9),I9*export_shares!Y9,"") -> 0.16924029 | ... AC9: =IF(ISNUMBER(N9*export_shares!AD9),N9*export_shares!AD9,"") | AD9: =SUM(Q9:AC9) -> 21.518954
A10: 1847 | B10: =IF(identifiers!B10=1,GBR!E10,"") -> 22.103578 | C10: =IF(identifiers!C10=1,FRA!F10,"") -> 15.606618 | D10: =IF(identifiers!D10=1,DEU!E10,"") -> 10.83435 | E10: =IF(identifiers!E10=1,ITA!E10,"") | F10: =IF(identifiers!F10=1,CAN!E10,"") | G10: =IF(identifiers!G10=1,CHE!E10,"") | H10: =IF(identifiers!H10=1,BEL!E10,"") -> 4.5643154 | I10: =IF(identifiers!I10=1,NLD!E10,"") -> 3.07147 | J10: =IF(identifiers!J10=1,PRT!E10,"") | K10: =IF(identifiers!K10=1,ESP!E10,"") | L10: =IF(identifiers!L10=1,JPN!E10,"") | M10: =IF(identifiers!M10=1,MEX!E10,"") | N10: =IF(identifiers!N10=1,BRA!E10,"") | P10: 1847 | Q10: =IF(ISNUMBER(B10*export_shares!R10),B10*export_shares!R10,"") -> 15.963125 | R10: =IF(ISNUMBER(C10*export_shares!S10),C10*export_shares!S10,"") -> 2.4593408 | S10: =IF(ISNUMBER(D10*export_shares!T10),D10*export_shares!T10,"") -> 0.44712189 | T10: =IF(ISNUMBER(E10*export_shares!U10),E10*export_shares!U10,"") | U10: =IF(ISNUMBER(F10*export_shares!V10),F10*export_shares!V10,"") | V10: =IF(ISNUMBER(G10*export_shares!W10),G10*export_shares!W10,"") | W10: =IF(ISNUMBER(H10*export_shares!X10),H10*export_shares!X10,"") -> 0.24672652 | X10: =IF(ISNUMBER(I10*export_shares!Y10),I10*export_shares!Y10,"") -> 0.076467075 | ... AC10: =IF(ISNUMBER(N10*export_shares!AD10),N10*export_shares!AD10,"") | AD10: =SUM(Q10:AC10) -> 19.192781
A11: 1848 | B11: =IF(identifiers!B11=1,GBR!E11,"") -> 22.543923 | C11: =IF(identifiers!C11=1,FRA!F11,"") -> 17.918877 | D11: =IF(identifiers!D11=1,DEU!E11,"") -> 9.9342868 | E11: =IF(identifiers!E11=1,ITA!E11,"") | F11: =IF(identifiers!F11=1,CAN!E11,"") | G11: =IF(identifiers!G11=1,CHE!E11,"") | H11: =IF(identifiers!H11=1,BEL!E11,"") -> 5.4945055 | I11: =IF(identifiers!I11=1,NLD!E11,"") -> 3.54493 | J11: =IF(identifiers!J11=1,PRT!E11,"") | K11: =IF(identifiers!K11=1,ESP!E11,"") | L11: =IF(identifiers!L11=1,JPN!E11,"") | M11: =IF(identifiers!M11=1,MEX!E11,"") | N11: =IF(identifiers!N11=1,BRA!E11,"") | P11: 1848 | Q11: =IF(ISNUMBER(B11*export_shares!R11),B11*export_shares!R11,"") -> 16.198616 | R11: =IF(ISNUMBER(C11*export_shares!S11),C11*export_shares!S11,"") -> 2.8800226 | S11: =IF(ISNUMBER(D11*export_shares!T11),D11*export_shares!T11,"") -> 0.42372813 | T11: =IF(ISNUMBER(E11*export_shares!U11),E11*export_shares!U11,"") | U11: =IF(ISNUMBER(F11*export_shares!V11),F11*export_shares!V11,"") | V11: =IF(ISNUMBER(G11*export_shares!W11),G11*export_shares!W11,"") | W11: =IF(ISNUMBER(H11*export_shares!X11),H11*export_shares!X11,"") -> 0.27206089 | X11: =IF(ISNUMBER(I11*export_shares!Y11),I11*export_shares!Y11,"") -> 0.10127998 | ... AC11: =IF(ISNUMBER(N11*export_shares!AD11),N11*export_shares!AD11,"") | AD11: =SUM(Q11:AC11) -> 19.875708
A12: 1849 | B12: =IF(identifiers!B12=1,GBR!E12,"") -> 22.799946 | C12: =IF(identifiers!C12=1,FRA!F12,"") -> 17.984858 | D12: =IF(identifiers!D12=1,DEU!E12,"") -> 11.470631 | E12: =IF(identifiers!E12=1,ITA!E12,"") | F12: =IF(identifiers!F12=1,CAN!E12,"") | G12: =IF(identifiers!G12=1,CHE!E12,"") | H12: =IF(identifiers!H12=1,BEL!E12,"") -> 5.7971014 | I12: =IF(identifiers!I12=1,NLD!E12,"") -> 3.383978 | J12: =IF(identifiers!J12=1,PRT!E12,"") | K12: =IF(identifiers!K12=1,ESP!E12,"") | L12: =IF(identifiers!L12=1,JPN!E12,"") | M12: =IF(identifiers!M12=1,MEX!E12,"") | N12: =IF(identifiers!N12=1,BRA!E12,"") | P12: 1849 | Q12: =IF(ISNUMBER(B12*export_shares!R12),B12*export_shares!R12,"") -> 16.836825 | R12: =IF(ISNUMBER(C12*export_shares!S12),C12*export_shares!S12,"") -> 2.2115785 | S12: =IF(ISNUMBER(D12*export_shares!T12),D12*export_shares!T12,"") -> 0.32393458 | T12: =IF(ISNUMBER(E12*export_shares!U12),E12*export_shares!U12,"") | U12: =IF(ISNUMBER(F12*export_shares!V12),F12*export_shares!V12,"") | V12: =IF(ISNUMBER(G12*export_shares!W12),G12*export_shares!W12,"") | W12: =IF(ISNUMBER(H12*export_shares!X12),H12*export_shares!X12,"") -> 0.43426857 | X12: =IF(ISNUMBER(I12*export_shares!Y12),I12*export_shares!Y12,"") -> 0.11986199 | ... AC12: =IF(ISNUMBER(N12*export_shares!AD12),N12*export_shares!AD12,"") | AD12: =SUM(Q12:AC12) -> 19.926468
A13: 1850 | B13: =IF(identifiers!B13=1,GBR!E13,"") -> 21.537061 | C13: =IF(identifiers!C13=1,FRA!F13,"") -> 16.521094 | D13: =IF(identifiers!D13=1,DEU!E13,"") -> 11.070954 | E13: =IF(identifiers!E13=1,ITA!E13,"") | F13: =IF(identifiers!F13=1,CAN!E13,"") | G13: =IF(identifiers!G13=1,CHE!E13,"") | H13: =IF(identifiers!H13=1,BEL!E13,"") -> 5.0632911 | I13: =IF(identifiers!I13=1,NLD!E13,"") -> 2.6595745 | J13: =IF(identifiers!J13=1,PRT!E13,"") | K13: =IF(identifiers!K13=1,ESP!E13,"") -> 24.137931 | L13: =IF(identifiers!L13=1,JPN!E13,"") | M13: =IF(identifiers!M13=1,MEX!E13,"") | N13: =IF(identifiers!N13=1,BRA!E13,"") | P13: 1850 | Q13: =IF(ISNUMBER(B13*export_shares!R13),B13*export_shares!R13,"") -> 14.34519 | R13: =IF(ISNUMBER(C13*export_shares!S13),C13*export_shares!S13,"") -> 2.7873598 | S13: =IF(ISNUMBER(D13*export_shares!T13),D13*export_shares!T13,"") -> 0.51633734 | T13: =IF(ISNUMBER(E13*export_shares!U13),E13*export_shares!U13,"") | U13: =IF(ISNUMBER(F13*export_shares!V13),F13*export_shares!V13,"") | V13: =IF(ISNUMBER(G13*export_shares!W13),G13*export_shares!W13,"") | W13: =IF(ISNUMBER(H13*export_shares!X13),H13*export_shares!X13,"") -> 0.31804625 | X13: =IF(ISNUMBER(I13*export_shares!Y13),I13*export_shares!Y13,"") -> 0.063677034 | ... AC13: =IF(ISNUMBER(N13*export_shares!AD13),N13*export_shares!AD13,"") | AD13: =SUM(Q13:AC13) -> 18.798659
A14: 1851 | B14: =IF(identifiers!B14=1,GBR!E14,"") -> 20.564321 | C14: =IF(identifiers!C14=1,FRA!F14,"") -> 15.711605 | D14: =IF(identifiers!D14=1,DEU!E14,"") -> 11.038591 | E14: =IF(identifiers!E14=1,ITA!E14,"") | F14: =IF(identifiers!F14=1,CAN!E14,"") | G14: =IF(identifiers!G14=1,CHE!E14,"") | H14: =IF(identifiers!H14=1,BEL!E14,"") -> 5.5045872 | I14: =IF(identifiers!I14=1,NLD!E14,"") -> 2.5 | J14: =IF(identifiers!J14=1,PRT!E14,"") | K14: =IF(identifiers!K14=1,ESP!E14,"") -> 23.668639 | L14: =IF(identifiers!L14=1,JPN!E14,"") | M14: =IF(identifiers!M14=1,MEX!E14,"") | N14: =IF(identifiers!N14=1,BRA!E14,"") | P14: 1851 | Q14: =IF(ISNUMBER(B14*export_shares!R14),B14*export_shares!R14,"") -> 15.008464 | R14: =IF(ISNUMBER(C14*export_shares!S14),C14*export_shares!S14,"") -> 2.3821031 | S14: =IF(ISNUMBER(D14*export_shares!T14),D14*export_shares!T14,"") -> 0.47586346 | T14: =IF(ISNUMBER(E14*export_shares!U14),E14*export_shares!U14,"") | U14: =IF(ISNUMBER(F14*export_shares!V14),F14*export_shares!V14,"") | V14: =IF(ISNUMBER(G14*export_shares!W14),G14*export_shares!W14,"") | W14: =IF(ISNUMBER(H14*export_shares!X14),H14*export_shares!X14,"") -> 0.18615071 | X14: =IF(ISNUMBER(I14*export_shares!Y14),I14*export_shares!Y14,"") -> 0.046377626 | ... AC14: =IF(ISNUMBER(N14*export_shares!AD14),N14*export_shares!AD14,"") | AD14: =SUM(Q14:AC14) -> 18.645183
... A187: 2024 | B187: =IF(identifiers!B187=1,GBR!E187,"") -> 0.85811976 | C187: =IF(identifiers!C187=1,FRA!F187,"") -> 0.47446964 | D187: =IF(identifiers!D187=1,DEU!E187,"") -> 0.42721077 | E187: =IF(identifiers!E187=1,ITA!E187,"") -> 0.52061587 | F187: =IF(identifiers!F187=1,CAN!E187,"") -> 0.74065424 | G187: =IF(identifiers!G187=1,CHE!E187,"") -> 0.55773049 | H187: =IF(identifiers!H187=1,BEL!E187,"") -> 0.36975064 | I187: =IF(identifiers!I187=1,NLD!E187,"") -> 0.44149426 | J187: =IF(identifiers!J187=1,PRT!E187,"") -> 0.30650615 | K187: =IF(identifiers!K187=1,ESP!E187,"") -> 0.61710505 | L187: =IF(identifiers!L187=1,JPN!E187,"") -> 0.8135491 | M187: =IF(identifiers!M187=1,MEX!E187,"") -> 1.2032003 | N187: =IF(identifiers!N187=1,BRA!E187,"") | P187: 2024 | Q187: =IF(ISNUMBER(B187*export_shares!R187),B187*export_shares!R187,"") -> 0.058373312 | R187: =IF(ISNUMBER(C187*export_shares!S187),C187*export_shares!S187,"") -> 0.017672506 | S187: =IF(ISNUMBER(D187*export_shares!T187),D187*export_shares!T187,"") -> 0.027669431 | T187: =IF(ISNUMBER(E187*export_shares!U187),E187*export_shares!U187,"") -> 0.014408315 | U187: =IF(ISNUMBER(F187*export_shares!V187),F187*export_shares!V187,"") -> 0.22166329 | V187: =IF(ISNUMBER(G187*export_shares!W187),G187*export_shares!W187,"") -> 0.011946246 | W187: =IF(ISNUMBER(H187*export_shares!X187),H187*export_shares!X187,"") -> 0.010815973 | X187: =IF(ISNUMBER(I187*export_shares!Y187),I187*export_shares!Y187,"") -> 0.033314209 | ... AC187: =IF(ISNUMBER(N187*export_shares!AD187),N187*export_shares!AD187,"") | AD187: =SUM(Q187:AC187) -> 0.80836768

Sheet export_shares
A1: Raw shares | D1: =IF(ISNUMBER(tau!D3),IF(ISNUMBER(GBR!R3),GBR!R3,""),"") | E1: =IF(ISNUMBER(tau!E3),IF(ISNUMBER(GBR!S3),GBR!S3,""),"") | F1: =IF(ISNUMBER(tau!F3),IF(ISNUMBER(GBR!T3),GBR!T3,""),"") | G1: =IF(ISNUMBER(tau!G3),IF(ISNUMBER(GBR!U3),GBR!U3,""),"") | H1: =IF(ISNUMBER(tau!H3),IF(ISNUMBER(GBR!V3),GBR!V3,""),"") | I1: =IF(ISNUMBER(tau!I3),IF(ISNUMBER(GBR!W3),GBR!W3,""),"") | J1: =IF(ISNUMBER(tau!J3),IF(ISNUMBER(GBR!X3),GBR!X3,""),"") | K1: =IF(ISNUMBER(tau!K3),IF(ISNUMBER(GBR!Y3),GBR!Y3,""),"") | ... N1: =IF(ISNUMBER(tau!N3),IF(ISNUMBER(GBR!AB3),GBR!AB3,""),"") | Q1: Normalized shares
A2: year | B2: GBR | C2: FRA | D2: DEU | E2: ITA | F2: CAN | G2: CHE | H2: BEL | I2: NLD | J2: PRT | K2: ESP | L2: JPN | M2: MEX | N2: BRA | O2: share in sample | Q2: year | R2: GBR | S2: FRA | T2: DEU | U2: ITA | V2: CAN | W2: CHE | X2: BEL | Y2: NLD | Z2: PRT | AA2: ESP | AB2: JPN | AC2: MEX | AD2: BRA | AE2: Total
A3: 1840 | B3: =IF(identifiers!B3=1,GBR!O3,"") -> 0.44422439 | C3: =IF(identifiers!C3=1,FRA!P3,"") -> 0.16139495 | D3: =IF(identifiers!D3=1,DEU!O3,"") | E3: =IF(identifiers!E3=1,ITA!N3,"") | F3: =IF(identifiers!F3=1,CAN!O3,"") | G3: =IF(identifiers!G3=1,CHE!N3,"") | H3: =IF(identifiers!H3=1,BEL!N3,"") | I3: =IF(identifiers!I3=1,NLD!N3,"") | J3: =IF(identifiers!J3=1,PRT!N3,"") | K3: =IF(identifiers!K3=1,ESP!N3,"") | L3: =IF(identifiers!L3=1,JPN!O3,"") | M3: =IF(identifiers!M3=1,MEX!O3,"") | N3: =IF(identifiers!N3=1,BRA!O3,"") | O3: =SUM(B3:N3) -> 0.60561934 | Q3: 1840 | R3: =IF(ISNUMBER(B3),B3/SUM($B3:$N3),"") -> 0.73350431 | S3: =IF(ISNUMBER(C3),C3/SUM($B3:$N3),"") -> 0.26649569 | T3: =IF(ISNUMBER(D3),D3/SUM($B3:$N3),"") | U3: =IF(ISNUMBER(E3),E3/SUM($B3:$N3),"") | V3: =IF(ISNUMBER(F3),F3/SUM($B3:$N3),"") | W3: =IF(ISNUMBER(G3),G3/SUM($B3:$N3),"") | X3: =IF(ISNUMBER(H3),H3/SUM($B3:$N3),"") | Y3: =IF(ISNUMBER(I3),I3/SUM($B3:$N3),"") | ... AD3: =IF(ISNUMBER(N3),N3/SUM($B3:$N3),"") | AE3: =SUM(R3:AD3) -> 1
A4: 1841 | B4: =IF(identifiers!B4=1,GBR!O4,"") -> 0.42028243 | C4: =IF(identifiers!C4=1,FRA!P4,"") -> 0.16081854 | D4: =IF(identifiers!D4=1,DEU!O4,"") | E4: =IF(identifiers!E4=1,ITA!N4,"") | F4: =IF(identifiers!F4=1,CAN!O4,"") | G4: =IF(identifiers!G4=1,CHE!N4,"") | H4: =IF(identifiers!H4=1,BEL!N4,"") | I4: =IF(identifiers!I4=1,NLD!N4,"") | J4: =IF(identifiers!J4=1,PRT!N4,"") | K4: =IF(identifiers!K4=1,ESP!N4,"") | L4: =IF(identifiers!L4=1,JPN!O4,"") | M4: =IF(identifiers!M4=1,MEX!O4,"") | N4: =IF(identifiers!N4=1,BRA!O4,"") | O4: =SUM(B4:N4) -> 0.58110096 | Q4: 1841 | R4: =IF(ISNUMBER(B4),B4/SUM($B4:$N4),"") -> 0.72325199 | S4: =IF(ISNUMBER(C4),C4/SUM($B4:$N4),"") -> 0.27674801 | T4: =IF(ISNUMBER(D4),D4/SUM($B4:$N4),"") | U4: =IF(ISNUMBER(E4),E4/SUM($B4:$N4),"") | V4: =IF(ISNUMBER(F4),F4/SUM($B4:$N4),"") | W4: =IF(ISNUMBER(G4),G4/SUM($B4:$N4),"") | X4: =IF(ISNUMBER(H4),H4/SUM($B4:$N4),"") | Y4: =IF(ISNUMBER(I4),I4/SUM($B4:$N4),"") | ... AD4: =IF(ISNUMBER(N4),N4/SUM($B4:$N4),"") | AE4: =SUM(R4:AD4) -> 1
A5: 1842 | B5: =IF(identifiers!B5=1,GBR!O5,"") -> 0.40060963 | C5: =IF(identifiers!C5=1,FRA!P5,"") -> 0.17011027 | D5: =IF(identifiers!D5=1,DEU!O5,"") | E5: =IF(identifiers!E5=1,ITA!N5,"") | F5: =IF(identifiers!F5=1,CAN!O5,"") | G5: =IF(identifiers!G5=1,CHE!N5,"") | H5: =IF(identifiers!H5=1,BEL!N5,"") | I5: =IF(identifiers!I5=1,NLD!N5,"") | J5: =IF(identifiers!J5=1,PRT!N5,"") | K5: =IF(identifiers!K5=1,ESP!N5,"") | L5: =IF(identifiers!L5=1,JPN!O5,"") | M5: =IF(identifiers!M5=1,MEX!O5,"") | N5: =IF(identifiers!N5=1,BRA!O5,"") | O5: =SUM(B5:N5) -> 0.57071991 | Q5: 1842 | R5: =IF(ISNUMBER(B5),B5/SUM($B5:$N5),"") -> 0.70193738 | S5: =IF(ISNUMBER(C5),C5/SUM($B5:$N5),"") -> 0.29806262 | T5: =IF(ISNUMBER(D5),D5/SUM($B5:$N5),"") | U5: =IF(ISNUMBER(E5),E5/SUM($B5:$N5),"") | V5: =IF(ISNUMBER(F5),F5/SUM($B5:$N5),"") | W5: =IF(ISNUMBER(G5),G5/SUM($B5:$N5),"") | X5: =IF(ISNUMBER(H5),H5/SUM($B5:$N5),"") | Y5: =IF(ISNUMBER(I5),I5/SUM($B5:$N5),"") | ... AD5: =IF(ISNUMBER(N5),N5/SUM($B5:$N5),"") | AE5: =SUM(R5:AD5) -> 1
A6: 1843 | B6: =IF(identifiers!B6=1,GBR!O6,"") -> 0.49472876 | C6: =IF(identifiers!C6=1,FRA!P6,"") -> 0.1446721 | D6: =IF(identifiers!D6=1,DEU!O6,"") | E6: =IF(identifiers!E6=1,ITA!N6,"") | F6: =IF(identifiers!F6=1,CAN!O6,"") | G6: =IF(identifiers!G6=1,CHE!N6,"") | H6: =IF(identifiers!H6=1,BEL!N6,"") | I6: =IF(identifiers!I6=1,NLD!N6,"") | J6: =IF(identifiers!J6=1,PRT!N6,"") | K6: =IF(identifiers!K6=1,ESP!N6,"") | L6: =IF(identifiers!L6=1,JPN!O6,"") | M6: =IF(identifiers!M6=1,MEX!O6,"") | N6: =IF(identifiers!N6=1,BRA!O6,"") | O6: =SUM(B6:N6) -> 0.63940086 | Q6: 1843 | R6: =IF(ISNUMBER(B6),B6/SUM($B6:$N6),"") -> 0.77373803 | S6: =IF(ISNUMBER(C6),C6/SUM($B6:$N6),"") -> 0.22626197 | T6: =IF(ISNUMBER(D6),D6/SUM($B6:$N6),"") | U6: =IF(ISNUMBER(E6),E6/SUM($B6:$N6),"") | V6: =IF(ISNUMBER(F6),F6/SUM($B6:$N6),"") | W6: =IF(ISNUMBER(G6),G6/SUM($B6:$N6),"") | X6: =IF(ISNUMBER(H6),H6/SUM($B6:$N6),"") | Y6: =IF(ISNUMBER(I6),I6/SUM($B6:$N6),"") | ... AD6: =IF(ISNUMBER(N6),N6/SUM($B6:$N6),"") | AE6: =SUM(R6:AD6) -> 1
A7: 1844 | B7: =IF(identifiers!B7=1,GBR!O7,"") -> 0.46296868 | C7: =IF(identifiers!C7=1,FRA!P7,"") -> 0.12272106 | D7: =IF(identifiers!D7=1,DEU!O7,"") | E7: =IF(identifiers!E7=1,ITA!N7,"") | F7: =IF(identifiers!F7=1,CAN!O7,"") | G7: =IF(identifiers!G7=1,CHE!N7,"") | H7: =IF(identifiers!H7=1,BEL!N7,"") | I7: =IF(identifiers!I7=1,NLD!N7,"") | J7: =IF(identifiers!J7=1,PRT!N7,"") | K7: =IF(identifiers!K7=1,ESP!N7,"") | L7: =IF(identifiers!L7=1,JPN!O7,"") | M7: =IF(identifiers!M7=1,MEX!O7,"") | N7: =IF(identifiers!N7=1,BRA!O7,"") | O7: =SUM(B7:N7) -> 0.58568974 | Q7: 1844 | R7: =IF(ISNUMBER(B7),B7/SUM($B7:$N7),"") -> 0.79046745 | S7: =IF(ISNUMBER(C7),C7/SUM($B7:$N7),"") -> 0.20953255 | T7: =IF(ISNUMBER(D7),D7/SUM($B7:$N7),"") | U7: =IF(ISNUMBER(E7),E7/SUM($B7:$N7),"") | V7: =IF(ISNUMBER(F7),F7/SUM($B7:$N7),"") | W7: =IF(ISNUMBER(G7),G7/SUM($B7:$N7),"") | X7: =IF(ISNUMBER(H7),H7/SUM($B7:$N7),"") | Y7: =IF(ISNUMBER(I7),I7/SUM($B7:$N7),"") | ... AD7: =IF(ISNUMBER(N7),N7/SUM($B7:$N7),"") | AE7: =SUM(R7:AD7) -> 1
A8: 1845 | B8: =IF(identifiers!B8=1,GBR!O8,"") -> 0.42517532 | C8: =IF(identifiers!C8=1,FRA!P8,"") -> 0.11328098 | D8: =IF(identifiers!D8=1,DEU!O8,"") | E8: =IF(identifiers!E8=1,ITA!N8,"") | F8: =IF(identifiers!F8=1,CAN!O8,"") | G8: =IF(identifiers!G8=1,CHE!N8,"") | H8: =IF(identifiers!H8=1,BEL!N8,"") | I8: =IF(identifiers!I8=1,NLD!N8,"") | J8: =IF(identifiers!J8=1,PRT!N8,"") | K8: =IF(identifiers!K8=1,ESP!N8,"") | L8: =IF(identifiers!L8=1,JPN!O8,"") | M8: =IF(identifiers!M8=1,MEX!O8,"") | N8: =IF(identifiers!N8=1,BRA!O8,"") | O8: =SUM(B8:N8) -> 0.5384563 | Q8: 1845 | R8: =IF(ISNUMBER(B8),B8/SUM($B8:$N8),"") -> 0.78961899 | S8: =IF(ISNUMBER(C8),C8/SUM($B8:$N8),"") -> 0.21038101 | T8: =IF(ISNUMBER(D8),D8/SUM($B8:$N8),"") | U8: =IF(ISNUMBER(E8),E8/SUM($B8:$N8),"") | V8: =IF(ISNUMBER(F8),F8/SUM($B8:$N8),"") | W8: =IF(ISNUMBER(G8),G8/SUM($B8:$N8),"") | X8: =IF(ISNUMBER(H8),H8/SUM($B8:$N8),"") | Y8: =IF(ISNUMBER(I8),I8/SUM($B8:$N8),"") | ... AD8: =IF(ISNUMBER(N8),N8/SUM($B8:$N8),"") | AE8: =SUM(R8:AD8) -> 1
A9: 1846 | B9: =IF(identifiers!B9=1,GBR!O9,"") -> 0.41881916 | C9: =IF(identifiers!C9=1,FRA!P9,"") -> 0.12735528 | D9: =IF(identifiers!D9=1,DEU!O9,"") | E9: =IF(identifiers!E9=1,ITA!N9,"") | F9: =IF(identifiers!F9=1,CAN!O9,"") | G9: =IF(identifiers!G9=1,CHE!N9,"") | H9: =IF(identifiers!H9=1,BEL!N9,"") -> 0.046664759 | I9: =IF(identifiers!I9=1,NLD!N9,"") -> 0.029623215 | J9: =IF(identifiers!J9=1,PRT!N9,"") | K9: =IF(identifiers!K9=1,ESP!N9,"") | L9: =IF(identifiers!L9=1,JPN!O9,"") | M9: =IF(identifiers!M9=1,MEX!O9,"") | N9: =IF(identifiers!N9=1,BRA!O9,"") | O9: =SUM(B9:N9) -> 0.62246242 | Q9: 1846 | R9: =IF(ISNUMBER(B9),B9/SUM($B9:$N9),"") -> 0.67284248 | S9: =IF(ISNUMBER(C9),C9/SUM($B9:$N9),"") -> 0.20459915 | T9: =IF(ISNUMBER(D9),D9/SUM($B9:$N9),"") | U9: =IF(ISNUMBER(E9),E9/SUM($B9:$N9),"") | V9: =IF(ISNUMBER(F9),F9/SUM($B9:$N9),"") | W9: =IF(ISNUMBER(G9),G9/SUM($B9:$N9),"") | X9: =IF(ISNUMBER(H9),H9/SUM($B9:$N9),"") -> 0.074967994 | Y9: =IF(ISNUMBER(I9),I9/SUM($B9:$N9),"") -> 0.047590368 | ... AD9: =IF(ISNUMBER(N9),N9/SUM($B9:$N9),"") | AE9: =SUM(R9:AD9) -> 1
A10: 1847 | B10: =IF(identifiers!B10=1,GBR!O10,"") -> 0.55498468 | C10: =IF(identifiers!C10=1,FRA!P10,"") -> 0.12109761 | D10: =IF(identifiers!D10=1,DEU!O10,"") -> 0.031713833 | E10: =IF(identifiers!E10=1,ITA!N10,"") | F10: =IF(identifiers!F10=1,CAN!O10,"") | G10: =IF(identifiers!G10=1,CHE!N10,"") | H10: =IF(identifiers!H10=1,BEL!N10,"") -> 0.041539939 | I10: =IF(identifiers!I10=1,NLD!N10,"") -> 0.019131713 | J10: =IF(identifiers!J10=1,PRT!N10,"") | K10: =IF(identifiers!K10=1,ESP!N10,"") | L10: =IF(identifiers!L10=1,JPN!O10,"") | M10: =IF(identifiers!M10=1,MEX!O10,"") | N10: =IF(identifiers!N10=1,BRA!O10,"") | O10: =SUM(B10:N10) -> 0.76846778 | Q10: 1847 | R10: =IF(ISNUMBER(B10),B10/SUM($B10:$N10),"") -> 0.72219643 | S10: =IF(ISNUMBER(C10),C10/SUM($B10:$N10),"") -> 0.1575832 | T10: =IF(ISNUMBER(D10),D10/SUM($B10:$N10),"") -> 0.041268917 | U10: =IF(ISNUMBER(E10),E10/SUM($B10:$N10),"") | V10: =IF(ISNUMBER(F10),F10/SUM($B10:$N10),"") | W10: =IF(ISNUMBER(G10),G10/SUM($B10:$N10),"") | X10: =IF(ISNUMBER(H10),H10/SUM($B10:$N10),"") -> 0.054055537 | Y10: =IF(ISNUMBER(I10),I10/SUM($B10:$N10),"") -> 0.024895921 | ... AD10: =IF(ISNUMBER(N10),N10/SUM($B10:$N10),"") | AE10: =SUM(R10:AD10) -> 1
A11: 1848 | B11: =IF(identifiers!B11=1,GBR!O11,"") -> 0.4862472 | C11: =IF(identifiers!C11=1,FRA!P11,"") -> 0.10876616 | D11: =IF(identifiers!D11=1,DEU!O11,"") -> 0.028864184 | E11: =IF(identifiers!E11=1,ITA!N11,"") | F11: =IF(identifiers!F11=1,CAN!O11,"") | G11: =IF(identifiers!G11=1,CHE!N11,"") | H11: =IF(identifiers!H11=1,BEL!N11,"") -> 0.033507821 | I11: =IF(identifiers!I11=1,NLD!N11,"") -> 0.019334129 | J11: =IF(identifiers!J11=1,PRT!N11,"") | K11: =IF(identifiers!K11=1,ESP!N11,"") | L11: =IF(identifiers!L11=1,JPN!O11,"") | M11: =IF(identifiers!M11=1,MEX!O11,"") | N11: =IF(identifiers!N11=1,BRA!O11,"") | O11: =SUM(B11:N11) -> 0.67671949 | Q11: 1848 | R11: =IF(ISNUMBER(B11),B11/SUM($B11:$N11),"") -> 0.71853583 | S11: =IF(ISNUMBER(C11),C11/SUM($B11:$N11),"") -> 0.16072562 | T11: =IF(ISNUMBER(D11),D11/SUM($B11:$N11),"") -> 0.0426531 | U11: =IF(ISNUMBER(E11),E11/SUM($B11:$N11),"") | V11: =IF(ISNUMBER(F11),F11/SUM($B11:$N11),"") | W11: =IF(ISNUMBER(G11),G11/SUM($B11:$N11),"") | X11: =IF(ISNUMBER(H11),H11/SUM($B11:$N11),"") -> 0.049515082 | Y11: =IF(ISNUMBER(I11),I11/SUM($B11:$N11),"") -> 0.028570374 | ... AD11: =IF(ISNUMBER(N11),N11/SUM($B11:$N11),"") | AE11: =SUM(R11:AD11) -> 1
A12: 1849 | B12: =IF(identifiers!B12=1,GBR!O12,"") -> 0.55799199 | C12: =IF(identifiers!C12=1,FRA!P12,"") -> 0.092917376 | D12: =IF(identifiers!D12=1,DEU!O12,"") -> 0.021338879 | E12: =IF(identifiers!E12=1,ITA!N12,"") | F12: =IF(identifiers!F12=1,CAN!O12,"") | G12: =IF(identifiers!G12=1,CHE!N12,"") | H12: =IF(identifiers!H12=1,BEL!N12,"") -> 0.056604256 | I12: =IF(identifiers!I12=1,NLD!N12,"") -> 0.026764278 | J12: =IF(identifiers!J12=1,PRT!N12,"") | K12: =IF(identifiers!K12=1,ESP!N12,"") | L12: =IF(identifiers!L12=1,JPN!O12,"") | M12: =IF(identifiers!M12=1,MEX!O12,"") | N12: =IF(identifiers!N12=1,BRA!O12,"") | O12: =SUM(B12:N12) -> 0.75561678 | Q12: 1849 | R12: =IF(ISNUMBER(B12),B12/SUM($B12:$N12),"") -> 0.73845897 | S12: =IF(ISNUMBER(C12),C12/SUM($B12:$N12),"") -> 0.12296892 | T12: =IF(ISNUMBER(D12),D12/SUM($B12:$N12),"") -> 0.028240346 | U12: =IF(ISNUMBER(E12),E12/SUM($B12:$N12),"") | V12: =IF(ISNUMBER(F12),F12/SUM($B12:$N12),"") | W12: =IF(ISNUMBER(G12),G12/SUM($B12:$N12),"") | X12: =IF(ISNUMBER(H12),H12/SUM($B12:$N12),"") -> 0.074911328 | Y12: =IF(ISNUMBER(I12),I12/SUM($B12:$N12),"") -> 0.035420439 | ... AD12: =IF(ISNUMBER(N12),N12/SUM($B12:$N12),"") | AE12: =SUM(R12:AD12) -> 1
A13: 1850 | B13: =IF(identifiers!B13=1,GBR!O13,"") -> 0.49380701 | C13: =IF(identifiers!C13=1,FRA!P13,"") -> 0.12508108 | D13: =IF(identifiers!D13=1,DEU!O13,"") -> 0.034576887 | E13: =IF(identifiers!E13=1,ITA!N13,"") | F13: =IF(identifiers!F13=1,CAN!O13,"") | G13: =IF(identifiers!G13=1,CHE!N13,"") | H13: =IF(identifiers!H13=1,BEL!N13,"") -> 0.046568771 | I13: =IF(identifiers!I13=1,NLD!N13,"") -> 0.017750397 | J13: =IF(identifiers!J13=1,PRT!N13,"") | K13: =IF(identifiers!K13=1,ESP!N13,"") -> 0.023589923 | L13: =IF(identifiers!L13=1,JPN!O13,"") | M13: =IF(identifiers!M13=1,MEX!O13,"") | N13: =IF(identifiers!N13=1,BRA!O13,"") | O13: =SUM(B13:N13) -> 0.74137408 | Q13: 1850 | R13: =IF(ISNUMBER(B13),B13/SUM($B13:$N13),"") -> 0.66606998 | S13: =IF(ISNUMBER(C13),C13/SUM($B13:$N13),"") -> 0.16871521 | T13: =IF(ISNUMBER(D13),D13/SUM($B13:$N13),"") -> 0.046638921 | U13: =IF(ISNUMBER(E13),E13/SUM($B13:$N13),"") | V13: =IF(ISNUMBER(F13),F13/SUM($B13:$N13),"") | W13: =IF(ISNUMBER(G13),G13/SUM($B13:$N13),"") | X13: =IF(ISNUMBER(H13),H13/SUM($B13:$N13),"") -> 0.062814135 | Y13: =IF(ISNUMBER(I13),I13/SUM($B13:$N13),"") -> 0.023942565 | ... AD13: =IF(ISNUMBER(N13),N13/SUM($B13:$N13),"") | AE13: =SUM(R13:AD13) -> 1
A14: 1851 | B14: =IF(identifiers!B14=1,GBR!O14,"") -> 0.53520599 | C14: =IF(identifiers!C14=1,FRA!P14,"") -> 0.11118319 | D14: =IF(identifiers!D14=1,DEU!O14,"") -> 0.031613154 | E14: =IF(identifiers!E14=1,ITA!N14,"") | F14: =IF(identifiers!F14=1,CAN!O14,"") | G14: =IF(identifiers!G14=1,CHE!N14,"") | H14: =IF(identifiers!H14=1,BEL!N14,"") -> 0.024799278 | I14: =IF(identifiers!I14=1,NLD!N14,"") -> 0.013604031 | J14: =IF(identifiers!J14=1,PRT!N14,"") | K14: =IF(identifiers!K14=1,ESP!N14,"") -> 0.016923758 | L14: =IF(identifiers!L14=1,JPN!O14,"") | M14: =IF(identifiers!M14=1,MEX!O14,"") | N14: =IF(identifiers!N14=1,BRA!O14,"") | O14: =SUM(B14:N14) -> 0.7333294 | Q14: 1851 | R14: =IF(ISNUMBER(B14),B14/SUM($B14:$N14),"") -> 0.72983027 | S14: =IF(ISNUMBER(C14),C14/SUM($B14:$N14),"") -> 0.15161425 | T14: =IF(ISNUMBER(D14),D14/SUM($B14:$N14),"") -> 0.043109078 | U14: =IF(ISNUMBER(E14),E14/SUM($B14:$N14),"") | V14: =IF(ISNUMBER(F14),F14/SUM($B14:$N14),"") | W14: =IF(ISNUMBER(G14),G14/SUM($B14:$N14),"") | X14: =IF(ISNUMBER(H14),H14/SUM($B14:$N14),"") -> 0.033817378 | Y14: =IF(ISNUMBER(I14),I14/SUM($B14:$N14),"") -> 0.01855105 | ... AD14: =IF(ISNUMBER(N14),N14/SUM($B14:$N14),"") | AE14: =SUM(R14:AD14) -> 1
... A187: 2024 | B187: =IF(identifiers!B187=1,GBR!O187,"") -> 0.038576134 | C187: =IF(identifiers!C187=1,FRA!P187,"") -> 0.021122338 | D187: =IF(identifiers!D187=1,DEU!O187,"") -> 0.036729102 | E187: =IF(identifiers!E187=1,ITA!N187,"") -> 0.015694522 | F187: =IF(identifiers!F187=1,CAN!O187,"") -> 0.16971903 | G187: =IF(identifiers!G187=1,CHE!N187,"") -> 0.01214673 | H187: =IF(identifiers!H187=1,BEL!N187,"") -> 0.016588569 | I187: =IF(identifiers!I187=1,NLD!N187,"") -> 0.042791422 | J187: =IF(identifiers!J187=1,PRT!N187,"") -> 0.0014344004 | K187: =IF(identifiers!K187=1,ESP!N187,"") -> 0.011962099 | L187: =IF(identifiers!L187=1,JPN!O187,"") -> 0.038307588 | M187: =IF(identifiers!M187=1,MEX!O187,"") -> 0.16201844 | N187: =IF(identifiers!N187=1,BRA!O187,"") | O187: =SUM(B187:N187) -> 0.56709038 | Q187: 2024 | R187: =IF(ISNUMBER(B187),B187/SUM($B187:$N187),"") -> 0.068024668 | S187: =IF(ISNUMBER(C187),C187/SUM($B187:$N187),"") -> 0.037246865 | T187: =IF(ISNUMBER(D187),D187/SUM($B187:$N187),"") -> 0.064767634 | U187: =IF(ISNUMBER(E187),E187/SUM($B187:$N187),"") -> 0.027675521 | V187: =IF(ISNUMBER(F187),F187/SUM($B187:$N187),"") -> 0.29928039 | W187: =IF(ISNUMBER(G187),G187/SUM($B187:$N187),"") -> 0.021419389 | X187: =IF(ISNUMBER(H187),H187/SUM($B187:$N187),"") -> 0.029252073 | Y187: =IF(ISNUMBER(I187),I187/SUM($B187:$N187),"") -> 0.075457853 | ... AD187: =IF(ISNUMBER(N187),N187/SUM($B187:$N187),"") | AE187: =SUM(R187:AD187) -> 1

Sheet identifiers
A1: Equals 1 if export weight and tau is not missing, 0 otherwise
A2: year | B2: GBR | C2: FRA | D2: DEU | E2: ITA | F2: CAN | G2: CHE | H2: BEL | I2: NLD | J2: PRT | K2: ESP | L2: JPN | M2: MEX | N2: BRA
A3: 1840 | B3: =GBR!R3 -> 1 | C3: =FRA!S3 -> 1 | D3: =DEU!R3 -> 0 | E3: =ITA!Q3 -> 0 | F3: =CAN!R3 -> 0 | G3: =CHE!Q3 -> 0 | H3: =BEL!Q3 -> 0 | I3: =NLD!Q3 -> 0 | J3: =PRT!Q3 -> 0 | K3: =ESP!Q3 -> 0 | L3: =JPN!R3 -> 0 | M3: =MEX!R3 -> 0 | N3: =BRA!R3 -> 0
A4: 1841 | B4: =GBR!R4 -> 1 | C4: =FRA!S4 -> 1 | D4: =DEU!R4 -> 0 | E4: =ITA!Q4 -> 0 | F4: =CAN!R4 -> 0 | G4: =CHE!Q4 -> 0 | H4: =BEL!Q4 -> 0 | I4: =NLD!Q4 -> 0 | J4: =PRT!Q4 -> 0 | K4: =ESP!Q4 -> 0 | L4: =JPN!R4 -> 0 | M4: =MEX!R4 -> 0 | N4: =BRA!R4 -> 0
A5: 1842 | B5: =GBR!R5 -> 1 | C5: =FRA!S5 -> 1 | D5: =DEU!R5 -> 0 | E5: =ITA!Q5 -> 0 | F5: =CAN!R5 -> 0 | G5: =CHE!Q5 -> 0 | H5: =BEL!Q5 -> 0 | I5: =NLD!Q5 -> 0 | J5: =PRT!Q5 -> 0 | K5: =ESP!Q5 -> 0 | L5: =JPN!R5 -> 0 | M5: =MEX!R5 -> 0 | N5: =BRA!R5 -> 0
A6: 1843 | B6: =GBR!R6 -> 1 | C6: =FRA!S6 -> 1 | D6: =DEU!R6 -> 0 | E6: =ITA!Q6 -> 0 | F6: =CAN!R6 -> 0 | G6: =CHE!Q6 -> 0 | H6: =BEL!Q6 -> 0 | I6: =NLD!Q6 -> 0 | J6: =PRT!Q6 -> 0 | K6: =ESP!Q6 -> 0 | L6: =JPN!R6 -> 0 | M6: =MEX!R6 -> 0 | N6: =BRA!R6 -> 0
A7: 1844 | B7: =GBR!R7 -> 1 | C7: =FRA!S7 -> 1 | D7: =DEU!R7 -> 0 | E7: =ITA!Q7 -> 0 | F7: =CAN!R7 -> 0 | G7: =CHE!Q7 -> 0 | H7: =BEL!Q7 -> 0 | I7: =NLD!Q7 -> 0 | J7: =PRT!Q7 -> 0 | K7: =ESP!Q7 -> 0 | L7: =JPN!R7 -> 0 | M7: =MEX!R7 -> 0 | N7: =BRA!R7 -> 0
A8: 1845 | B8: =GBR!R8 -> 1 | C8: =FRA!S8 -> 1 | D8: =DEU!R8 -> 0 | E8: =ITA!Q8 -> 0 | F8: =CAN!R8 -> 0 | G8: =CHE!Q8 -> 0 | H8: =BEL!Q8 -> 0 | I8: =NLD!Q8 -> 0 | J8: =PRT!Q8 -> 0 | K8: =ESP!Q8 -> 0 | L8: =JPN!R8 -> 0 | M8: =MEX!R8 -> 0 | N8: =BRA!R8 -> 0
A9: 1846 | B9: =GBR!R9 -> 1 | C9: =FRA!S9 -> 1 | D9: =DEU!R9 -> 0 | E9: =ITA!Q9 -> 0 | F9: =CAN!R9 -> 0 | G9: =CHE!Q9 -> 0 | H9: =BEL!Q9 -> 1 | I9: =NLD!Q9 -> 1 | J9: =PRT!Q9 -> 0 | K9: =ESP!Q9 -> 0 | L9: =JPN!R9 -> 0 | M9: =MEX!R9 -> 0 | N9: =BRA!R9 -> 0
A10: 1847 | B10: =GBR!R10 -> 1 | C10: =FRA!S10 -> 1 | D10: =DEU!R10 -> 1 | E10: =ITA!Q10 -> 0 | F10: =CAN!R10 -> 0 | G10: =CHE!Q10 -> 0 | H10: =BEL!Q10 -> 1 | I10: =NLD!Q10 -> 1 | J10: =PRT!Q10 -> 0 | K10: =ESP!Q10 -> 0 | L10: =JPN!R10 -> 0 | M10: =MEX!R10 -> 0 | N10: =BRA!R10 -> 0
A11: 1848 | B11: =GBR!R11 -> 1 | C11: =FRA!S11 -> 1 | D11: =DEU!R11 -> 1 | E11: =ITA!Q11 -> 0 | F11: =CAN!R11 -> 0 | G11: =CHE!Q11 -> 0 | H11: =BEL!Q11 -> 1 | I11: =NLD!Q11 -> 1 | J11: =PRT!Q11 -> 0 | K11: =ESP!Q11 -> 0 | L11: =JPN!R11 -> 0 | M11: =MEX!R11 -> 0 | N11: =BRA!R11 -> 0
A12: 1849 | B12: =GBR!R12 -> 1 | C12: =FRA!S12 -> 1 | D12: =DEU!R12 -> 1 | E12: =ITA!Q12 -> 0 | F12: =CAN!R12 -> 0 | G12: =CHE!Q12 -> 0 | H12: =BEL!Q12 -> 1 | I12: =NLD!Q12 -> 1 | J12: =PRT!Q12 -> 0 | K12: =ESP!Q12 -> 0 | L12: =JPN!R12 -> 0 | M12: =MEX!R12 -> 0 | N12: =BRA!R12 -> 0
A13: 1850 | B13: =GBR!R13 -> 1 | C13: =FRA!S13 -> 1 | D13: =DEU!R13 -> 1 | E13: =ITA!Q13 -> 0 | F13: =CAN!R13 -> 0 | G13: =CHE!Q13 -> 0 | H13: =BEL!Q13 -> 1 | I13: =NLD!Q13 -> 1 | J13: =PRT!Q13 -> 0 | K13: =ESP!Q13 -> 1 | L13: =JPN!R13 -> 0 | M13: =MEX!R13 -> 0 | N13: =BRA!R13 -> 0
A14: 1851 | B14: =GBR!R14 -> 1 | C14: =FRA!S14 -> 1 | D14: =DEU!R14 -> 1 | E14: =ITA!Q14 -> 0 | F14: =CAN!R14 -> 0 | G14: =CHE!Q14 -> 0 | H14: =BEL!Q14 -> 1 | I14: =NLD!Q14 -> 1 | J14: =PRT!Q14 -> 0 | K14: =ESP!Q14 -> 1 | L14: =JPN!R14 -> 0 | M14: =MEX!R14 -> 0 | N14: =BRA!R14 -> 0
... A187: 2024 | B187: =GBR!R187 -> 1 | C187: =FRA!S187 -> 1 | D187: =DEU!R187 -> 1 | E187: =ITA!Q187 -> 1 | F187: =CAN!R187 -> 1 | G187: =CHE!Q187 -> 1 | H187: =BEL!Q187 -> 1 | I187: =NLD!Q187 -> 1 | J187: =PRT!Q187 -> 1 | K187: =ESP!Q187 -> 1 | L187: =JPN!R187 -> 1 | M187: =MEX!R187 -> 1 | N187: =BRA!R187 -> 0

Sheet GBR
A1: GBR | B1: Avg tariff rate | G1: Export shares
A2: year | B2: tau_gbr_Imlah | C2: tau_gbr_tradhist | D2: tau_gbr_oecd | E2: tau_gbr_own | G2: year | H2: xpshr_gbr_tradhist | I2: total_exports_hsus | J2: exports_hsus | K2: xpshr_gbr_hsus | L2: total_exports_usitc | M2: exports_usitc | N2: xpshr_gbr_usitc | O2: xpshr_gbr_own | Q2: year | R2: Identifier
A3: 1840 | B3: 24.988867 | C3: 25.4386 | E3: =B3 -> 24.988867 | G3: 1840 | H3: 0.4838587 | I3: 124 | J3: 55 | K3: =J3/I3 -> 0.44354839 | O3: =K3/K4*O4 -> 0.44422439 | Q3: 1840 | R3: =ISNUMBER(O3)*ISNUMBER(E3) -> 1
A4: 1841 | B4: 26.810364 | C4: 27.89035 | E4: =B4 -> 26.810364 | G4: 1841 | H4: 0.451923 | I4: 112 | J4: 47 | K4: =J4/I4 -> 0.41964286 | O4: =K4/K5*O5 -> 0.42028243 | Q4: 1841 | R4: =ISNUMBER(O4)*ISNUMBER(E4) -> 1
A5: 1842 | B5: 29.552366 | C5: 30.75916 | E5: =B5 -> 29.552366 | G5: 1842 | H5: 0.4347826 | I5: 100 | J5: 40 | K5: =J5/I5 -> 0.4 | O5: =K5/K6*O6 -> 0.40060963 | Q5: 1842 | R5: =ISNUMBER(O5)*ISNUMBER(E5) -> 1
A6: 1843 | B6: 31.120124 | C6: 31.83099 | E6: =B6 -> 31.120124 | G6: 1843 | H6: 0.525641 | I6: 83 | J6: 41 | K6: =J6/I6 -> 0.4939759 | O6: =K6/K7*O7 -> 0.49472876 | Q6: 1843 | R6: =ISNUMBER(O6)*ISNUMBER(E6) -> 1
A7: 1844 | B7: 29.617214 | C7: 28.64385 | E7: =B7 -> 29.617214 | G7: 1844 | H7: 0.49 | I7: 106 | J7: 49 | K7: =J7/I7 -> 0.46226415 | O7: =K7/K8*O8 -> 0.46296868 | Q7: 1844 | R7: =ISNUMBER(O7)*ISNUMBER(E7) -> 1
A8: 1845 | B8: 27.585237 | C8: 27.26244 | E8: =B8 -> 27.585237 | G8: 1845 | H8: 0.4591837 | I8: 106 | J8: 45 | K8: =J8/I8 -> 0.4245283 | O8: =K8/K9*O9 -> 0.42517532 | Q8: 1845 | R8: =ISNUMBER(O8)*ISNUMBER(E8) -> 1
A9: 1846 | B9: 25.79171 | C9: 24.97136 | E9: =B9 -> 25.79171 | G9: 1846 | H9: 0.4509804 | I9: 110 | J9: 46 | K9: =J9/I9 -> 0.41818182 | O9: =K9/K10*O10 -> 0.41881916 | Q9: 1846 | R9: =ISNUMBER(O9)*ISNUMBER(E9) -> 1
A10: 1847 | B10: 22.103578 | C10: 19.80375 | E10: =B10 -> 22.103578 | G10: 1847 | H10: 0.5761589 | I10: 157 | J10: 87 | K10: =J10/I10 -> 0.55414013 | O10: =K10/K11*O11 -> 0.55498468 | Q10: 1847 | R10: =ISNUMBER(O10)*ISNUMBER(E10) -> 1
A11: 1848 | B11: 22.543923 | C11: 24.60317 | E11: =B11 -> 22.543923 | G11: 1848 | H11: 0.5153846 | I11: 138 | J11: 67 | K11: =J11/I11 -> 0.48550725 | O11: =K11/K12*O12 -> 0.4862472 | Q11: 1848 | R11: =ISNUMBER(O11)*ISNUMBER(E11) -> 1
A12: 1849 | B12: 22.799946 | C12: 22.28797 | E12: =B12 -> 22.799946 | G12: 1849 | H12: 0.5909091 | I12: 140 | J12: 78 | K12: =J12/I12 -> 0.55714286 | O12: =K12/K13*O13 -> 0.55799199 | Q12: 1849 | R12: =ISNUMBER(O12)*ISNUMBER(E12) -> 1
A13: 1850 | B13: 21.537061 | C13: 21.65049 | E13: =B13 -> 21.537061 | G13: 1850 | H13: 0.5259259 | I13: 144 | J13: 71 | K13: =J13/I13 -> 0.49305556 | O13: =K13/K14*O14 -> 0.49380701 | Q13: 1850 | R13: =ISNUMBER(O13)*ISNUMBER(E13) -> 1
A14: 1851 | B14: 20.564321 | C14: 20.09132 | E14: =B14 -> 20.564321 | G14: 1851 | H14: 0.5642458 | I14: 189 | J14: 101 | K14: =J14/I14 -> 0.53439153 | O14: =K14/K15*O15 -> 0.53520599 | Q14: 1851 | R14: =ISNUMBER(O14)*ISNUMBER(E14) -> 1
... A127: 1964 | B127: 3.8326253 | C127: 3.704403 | E127: =B127 -> 3.8326253 | G127: 1964 | H127: 0.0578615 | I127: 26508 | J127: 1532 | K127: =J127/I127 -> 0.057793874 | O127: =K127/K128*O128 -> 0.057881956 | Q127: 1964 | R127: =ISNUMBER(O127)*ISNUMBER(E127) -> 1
A128: 1965 | B128: 5.5080558 | C128: 6.022903 | D128: =INDEX('OECD tau'!$AT$10:$BM$69,MATCH($A128,'OECD tau'!$AS$10:$AS$69,0),MATCH($A$1,'OECD tau'!$AT$8:$BM$8,0)) -> 5.9548611 | E128: =B128 -> 5.5080558 | G128: 1965 | H128: 0.0586385 | I128: 27470 | J128: 1615 | K128: =J128/I128 -> 0.058791409 | O128: =K128/K129*O129 -> 0.058881012 | Q128: 1965 | R128: =ISNUMBER(O128)*ISNUMBER(E128) -> 1
A129: 1966 | B129: 5.6494739 | C129: 5.291599 | D129: =INDEX('OECD tau'!$AT$10:$BM$69,MATCH($A129,'OECD tau'!$AS$10:$AS$69,0),MATCH($A$1,'OECD tau'!$AT$8:$BM$8,0)) -> 5.2923387 | E129: =B129 -> 5.6494739 | G129: 1966 | H129: 0.056153 | I129: 30320 | J129: 1737 | K129: =J129/I129 -> 0.057288918 | O129: =K129/K130*O130 -> 0.057376231 | Q129: 1966 | R129: =ISNUMBER(O129)*ISNUMBER(E129) -> 1
A130: 1967 | B130: 3.7567409 | C130: 2.576738 | D130: =INDEX('OECD tau'!$AT$10:$BM$69,MATCH($A130,'OECD tau'!$AS$10:$AS$69,0),MATCH($A$1,'OECD tau'!$AT$8:$BM$8,0)) -> 2.9347826 | E130: =B130 -> 3.7567409 | G130: 1967 | H130: 0.0600905 | I130: 31526 | J130: 1960 | K130: =J130/I130 -> 0.062170907 | O130: =K130/K131*O131 -> 0.06226566 | Q130: 1967 | R130: =ISNUMBER(O130)*ISNUMBER(E130) -> 1
A131: 1968 | B131: 2.6972884 | C131: 2.786885 | D131: =INDEX('OECD tau'!$AT$10:$BM$69,MATCH($A131,'OECD tau'!$AS$10:$AS$69,0),MATCH($A$1,'OECD tau'!$AT$8:$BM$8,0)) -> 2.8101266 | E131: =B131 -> 2.6972884 | G131: 1968 | H131: 0.063669 | I131: 34636 | J131: 2289 | K131: =J131/I131 -> 0.066087308 | O131: =K131/K132*O132 -> 0.066188031 | Q131: 1968 | R131: =ISNUMBER(O131)*ISNUMBER(E131) -> 1
A132: 1969 | B132: 2.7292402 | C132: 2.645808 | D132: =INDEX('OECD tau'!$AT$10:$BM$69,MATCH($A132,'OECD tau'!$AS$10:$AS$69,0),MATCH($A$1,'OECD tau'!$AT$8:$BM$8,0)) -> 2.6451846 | E132: =B132 -> 2.7292402 | G132: 1969 | H132: 0.0594281 | I132: 38006 | J132: 2335 | K132: =J132/I132 -> 0.061437668 | O132: =K132/K133*O133 -> 0.061531304 | Q132: 1969 | R132: =ISNUMBER(O132)*ISNUMBER(E132) -> 1
A133: 1970 | B133: 2.8417802 | C133: 2.749997 | D133: =INDEX('OECD tau'!$AT$10:$BM$69,MATCH($A133,'OECD tau'!$AS$10:$AS$69,0),MATCH($A$1,'OECD tau'!$AT$8:$BM$8,0)) -> 2.6559014 | E133: =B133 -> 2.8417802 | G133: 1970 | H133: 0.0570267 | I133: 43224 | J133: 2536 | K133: =J133/I133 -> 0.058671109 | O133: =K133/K134*O134 -> 0.058760528 | Q133: 1970 | R133: =ISNUMBER(O133)*ISNUMBER(E133) -> 1
A134: 1971 | B134: 2.8205744 | C134: 2.812207 | D134: =INDEX('OECD tau'!$AT$10:$BM$69,MATCH($A134,'OECD tau'!$AS$10:$AS$69,0),MATCH($A$1,'OECD tau'!$AT$8:$BM$8,0)) -> 2.6592578 | E134: =B134 -> 2.8205744 | G134: 1971 | H134: 0.0577899 | I134: 44130 | J134: 2369 | K134: =J134/I134 -> 0.053682302 | O134: =K134/K135*O135 -> 0.053764119 | Q134: 1971 | R134: =ISNUMBER(O134)*ISNUMBER(E134) -> 1
A135: 1972 | B135: 3.0629141 | C135: 2.930185 | D135: =INDEX('OECD tau'!$AT$10:$BM$69,MATCH($A135,'OECD tau'!$AS$10:$AS$69,0),MATCH($A$1,'OECD tau'!$AT$8:$BM$8,0)) -> 3.1070704 | E135: =B135 -> 3.0629141 | G135: 1972 | H135: 0.0576833 | I135: 49779 | J135: 2658 | K135: =J135/I135 -> 0.05339601 | O135: =K135/K136*O136 -> 0.05347739 | Q135: 1972 | R135: =ISNUMBER(O135)*ISNUMBER(E135) -> 1
A136: 1973 | B136: 3.8028534 | C136: 4.219157 | D136: =INDEX('OECD tau'!$AT$10:$BM$69,MATCH($A136,'OECD tau'!$AS$10:$AS$69,0),MATCH($A$1,'OECD tau'!$AT$8:$BM$8,0)) -> 4.4469288 | E136: =B136 -> 3.8028534 | G136: 1973 | H136: 0.0551165 | I136: 71339 | J136: 3564 | K136: =J136/I136 -> 0.049958648 | O136: =K136/K137*O137 -> 0.050034789 | Q136: 1973 | R136: =ISNUMBER(O136)*ISNUMBER(E136) -> 1
A137: 1974 | B137: 3.365664 | C137: 2.285211 | D137: =INDEX('OECD tau'!$AT$10:$BM$69,MATCH($A137,'OECD tau'!$AS$10:$AS$69,0),MATCH($A$1,'OECD tau'!$AT$8:$BM$8,0)) -> 2.2744665 | E137: =B137 -> 3.365664 | G137: 1974 | H137: 0.0525137 | I137: 98507 | J137: 4574 | K137: =J137/I137 -> 0.046433248 | O137: =K137/K138*O138 -> 0.046504016 | Q137: 1974 | R137: =ISNUMBER(O137)*ISNUMBER(E137) -> 1
A138: 1975 | B138: 2.2163941 | C138: 2.014378 | D138: =INDEX('OECD tau'!$AT$10:$BM$69,MATCH($A138,'OECD tau'!$AS$10:$AS$69,0),MATCH($A$1,'OECD tau'!$AT$8:$BM$8,0)) -> 2.2078665 | E138: =B138 -> 2.2163941 | G138: 1975 | H138: 0.0484996 | I138: 107592 | J138: 4527 | K138: =J138/I138 -> 0.042075619 | O138: =K138/K139*O139 -> 0.042139746 | Q138: 1975 | R138: =ISNUMBER(O138)*ISNUMBER(E138) -> 1
A139: 1976 | B139: 2.0508564 | C139: 1.997878 | D139: =INDEX('OECD tau'!$AT$10:$BM$69,MATCH($A139,'OECD tau'!$AS$10:$AS$69,0),MATCH($A$1,'OECD tau'!$AT$8:$BM$8,0)) -> 2.0670778 | E139: =B139 -> 2.0508564 | G139: 1976 | H139: 0.0482269 | I139: 114992 | J139: 4801 | K139: =J139/I139 -> 0.04175073 | O139: =K139/K140*O140 -> 0.041814362 | Q139: 1976 | R139: =ISNUMBER(O139)*ISNUMBER(E139) -> 1
... A151: 1988 | B151: 1.8868831 | C151: 1.731186 | D151: =INDEX('OECD tau'!$AT$10:$BM$69,MATCH($A151,'OECD tau'!$AS$10:$AS$69,0),MATCH($A$1,'OECD tau'!$AT$8:$BM$8,0)) -> 1.7032338 | E151: =B151 -> 1.8868831 | G151: 1988 | H151: 0.0581223 | I151: 322426 | J151: 18364 | K151: =J151/I151 -> 0.056955705 | O151: =K151/K152*O152 -> 0.05704251 | Q151: 1988 | R151: =ISNUMBER(O151)*ISNUMBER(E151) -> 1
A152: 1989 | B152: 1.6725487 | C152: 1.557322 | D152: =INDEX('OECD tau'!$AT$10:$BM$69,MATCH($A152,'OECD tau'!$AS$10:$AS$69,0),MATCH($A$1,'OECD tau'!$AT$8:$BM$8,0)) -> 1.5833798 | E152: =B152 -> 1.6725487 | G152: 1989 | H152: 0.0597375 | I152: 363812 | J152: 20837 | K152: =J152/I152 -> 0.057274087 | L152: 363765.5 | M152: 20866.09 | N152: =M152/L152 -> 0.057361377 | O152: =N152 -> 0.057361377 | Q152: 1989 | R152: =ISNUMBER(O152)*ISNUMBER(E152) -> 1
A153: 1990 | B153: 1.5655022 | C153: 1.589478 | D153: =INDEX('OECD tau'!$AT$10:$BM$69,MATCH($A153,'OECD tau'!$AS$10:$AS$69,0),MATCH($A$1,'OECD tau'!$AT$8:$BM$8,0)) -> 1.4569305 | E153: =B153 -> 1.5655022 | G153: 1990 | H153: 0.0616041 | I153: 393592 | J153: 23049 | K153: =J153/I153 -> 0.058560641 | L153: 392975.79 | M153: 23484.08 | N153: =M153/L153 -> 0.05975961 | O153: =N153 -> 0.05975961 | Q153: 1990 | R153: =ISNUMBER(O153)*ISNUMBER(E153) -> 1
A154: 1991 | B154: 1.7074279 | C154: 1.697741 | D154: =INDEX('OECD tau'!$AT$10:$BM$69,MATCH($A154,'OECD tau'!$AS$10:$AS$69,0),MATCH($A$1,'OECD tau'!$AT$8:$BM$8,0)) -> 1.6034188 | E154: =B154 -> 1.7074279 | G154: 1991 | H154: 0.0543612 | I154: 421730 | J154: 22046 | K154: =J154/I154 -> 0.052275152 | L154: 421853.58 | M154: 22063.59 | N154: =M154/L154 -> 0.052301536 | O154: =N154 -> 0.052301536 | Q154: 1991 | R154: =ISNUMBER(O154)*ISNUMBER(E154) -> 1
A155: 1992 | B155: 1.6489066 | C155: 1.324107 | D155: =INDEX('OECD tau'!$AT$10:$BM$69,MATCH($A155,'OECD tau'!$AS$10:$AS$69,0),MATCH($A$1,'OECD tau'!$AT$8:$BM$8,0)) -> 1.5436929 | E155: =B155 -> 1.6489066 | G155: 1992 | H155: 0.0509426 | I155: 448164 | J155: 22800 | K155: =J155/I155 -> 0.050874234 | L155: 447471.02 | M155: 22808.2 | N155: =M155/L155 -> 0.050971346 | O155: =N155 -> 0.050971346 | Q155: 1992 | R155: =ISNUMBER(O155)*ISNUMBER(E155) -> 1
A156: 1993 | B156: 1.3911341 | C156: 1.565047 | D156: =INDEX('OECD tau'!$AT$10:$BM$69,MATCH($A156,'OECD tau'!$AS$10:$AS$69,0),MATCH($A$1,'OECD tau'!$AT$8:$BM$8,0)) -> 1.5949947 | E156: =B156 -> 1.3911341 | G156: 1993 | H156: 0.0498644 | I156: 465091 | J156: 26438 | K156: =J156/I156 -> 0.05684479 | L156: 464858.41 | M156: 26375.94 | N156: =M156/L156 -> 0.056739729 | O156: =N156 -> 0.056739729 | Q156: 1993 | R156: =ISNUMBER(O156)*ISNUMBER(E156) -> 1
A157: 1994 | B157: 1.4179993 | C157: 1.472948 | D157: =INDEX('OECD tau'!$AT$10:$BM$69,MATCH($A157,'OECD tau'!$AS$10:$AS$69,0),MATCH($A$1,'OECD tau'!$AT$8:$BM$8,0)) -> 1.4237297 | E157: =B157 -> 1.4179993 | G157: 1994 | H157: 0.0488439 | I157: 512627 | J157: 26900 | K157: =J157/I157 -> 0.052474801 | L157: 512415.61 | M157: 26832.72 | N157: =M157/L157 -> 0.052365149 | O157: =N157 -> 0.052365149 | Q157: 1994 | R157: =ISNUMBER(O157)*ISNUMBER(E157) -> 1
A158: 1995 | B158: 1.556829 | C158: 1.451329 | D158: =INDEX('OECD tau'!$AT$10:$BM$69,MATCH($A158,'OECD tau'!$AS$10:$AS$69,0),MATCH($A$1,'OECD tau'!$AT$8:$BM$8,0)) -> 1.4492155 | E158: =B158 -> 1.556829 | G158: 1995 | H158: 0.0500691 | I158: 584742 | J158: 28857 | K158: =J158/I158 -> 0.04934997 | L158: 582119.67 | M158: 28826.89 | N158: =M158/L158 -> 0.049520556 | O158: =N158 -> 0.049520556 | Q158: 1995 | R158: =ISNUMBER(O158)*ISNUMBER(E158) -> 1
A159: 1996 | B159: 1.4609486 | C159: 1.389438 | D159: =INDEX('OECD tau'!$AT$10:$BM$69,MATCH($A159,'OECD tau'!$AS$10:$AS$69,0),MATCH($A$1,'OECD tau'!$AT$8:$BM$8,0)) -> 1.2452123 | E159: =B159 -> 1.4609486 | G159: 1996 | H159: 0.051925 | I159: 625075 | J159: 30963 | K159: =J159/I159 -> 0.049534856 | L159: 622827.06 | M159: 30916 | N159: =M159/L159 -> 0.049638177 | O159: =N159 -> 0.049638177 | Q159: 1996 | R159: =ISNUMBER(O159)*ISNUMBER(E159) -> 1
A160: 1997 | B160: 1.4354006 | C160: 1.248237 | D160: =INDEX('OECD tau'!$AT$10:$BM$69,MATCH($A160,'OECD tau'!$AS$10:$AS$69,0),MATCH($A$1,'OECD tau'!$AT$8:$BM$8,0)) -> 1.2114834 | E160: =B160 -> 1.4354006 | G160: 1997 | H160: 0.05613 | I160: 689182 | J160: 36425 | K160: =J160/I160 -> 0.052852512 | L160: 687598 | M160: 36435.09 | N160: =M160/L160 -> 0.052988941 | O160: =N160 -> 0.052988941 | Q160: 1997 | R160: =ISNUMBER(O160)*ISNUMBER(E160) -> 1
A161: 1998 | C161: 0.1559299 | D161: =INDEX('OECD tau'!$AT$10:$BM$69,MATCH($A161,'OECD tau'!$AS$10:$AS$69,0),MATCH($A$1,'OECD tau'!$AT$8:$BM$8,0)) -> 1.1013286 | E161: =D161 -> 1.1013286 | G161: 1998 | H161: 0.0582118 | I161: 682138 | J161: 39058 | K161: =J161/I161 -> 0.057258209 | L161: 680474.25 | M161: 39070.2 | N161: =M161/L161 -> 0.057416133 | O161: =N161 -> 0.057416133 | Q161: 1998 | R161: =ISNUMBER(O161)*ISNUMBER(E161) -> 1
A162: 1999 | C162: 0.1584253 | D162: =INDEX('OECD tau'!$AT$10:$BM$69,MATCH($A162,'OECD tau'!$AS$10:$AS$69,0),MATCH($A$1,'OECD tau'!$AT$8:$BM$8,0)) -> 1.0325361 | E162: =D162 -> 1.0325361 | G162: 1999 | H162: 0.0550308 | I162: 695797 | J162: 38407 | K162: =J162/I162 -> 0.055198571 | L162: 692820.62 | M162: 38337.79 | N162: =M162/L162 -> 0.05533581 | O162: =N162 -> 0.05533581 | Q162: 1999 | R162: =ISNUMBER(O162)*ISNUMBER(E162) -> 1
A163: 2000 | C163: 0.1272159 | D163: =INDEX('OECD tau'!$AT$10:$BM$69,MATCH($A163,'OECD tau'!$AS$10:$AS$69,0),MATCH($A$1,'OECD tau'!$AT$8:$BM$8,0)) -> 0.93987249 | E163: =D163 -> 0.93987249 | G163: 2000 | H163: 0.0547095 | I163: 781918 | J163: 41570 | K163: =J163/I163 -> 0.053164143 | L163: 780418.63 | M163: 41579.36 | N163: =M163/L163 -> 0.053278277 | O163: =N163 -> 0.053278277 | Q163: 2000 | R163: =ISNUMBER(O163)*ISNUMBER(E163) -> 1
...

Sheet FRA
A1: FRA | B1: Avg tariff rate | H1: Export shares
A2: year | B2: tau_fra_mitchell | C2: tau_fra_levyleboyer | D2: tau_fra_tradhist | E2: tau_fra_oecd | F2: tau_fra_own | H2: year | I2: xpshr_fra_tradhist | J2: total_exports_hsus | K2: exports_hsus | L2: xpshr_fra_hsus | M2: total_exports_usitc | N2: exports_usitc | O2: xpshr_fra_usitc | P2: xpshr_fra_own | R2: year | S2: Identifier
A3: 1840 | C3: 17.8982 | D3: 17.9 | F3: =C3 -> 17.8982 | H3: 1840 | I3: 0.3104753 | J3: 124 | K3: 20 | L3: =K3/J3 -> 0.16129032 | P3: =L3/L4*P4 -> 0.16139495 | R3: 1840 | S3: =ISNUMBER(P3)*ISNUMBER(F3) -> 1
A4: 1841 | C4: 17.8982 | D4: 17.9 | F4: =C4 -> 17.8982 | H4: 1841 | I4: 0.2293399 | J4: 112 | K4: 18 | L4: =K4/J4 -> 0.16071429 | P4: =L4/L5*P5 -> 0.16081854 | R4: 1841 | S4: =ISNUMBER(P4)*ISNUMBER(F4) -> 1
A5: 1842 | C5: 17.898219 | D5: 17.9 | F5: =C5 -> 17.898219 | H5: 1842 | I5: 0.2755317 | J5: 100 | K5: 17 | L5: =K5/J5 -> 0.17 | P5: =L5/L6*P6 -> 0.17011027 | R5: 1842 | S5: =ISNUMBER(P5)*ISNUMBER(F5) -> 1
A6: 1843 | C6: 17.854714 | D6: 17.9 | F6: =C6 -> 17.854714 | H6: 1843 | I6: 0.3453806 | J6: 83 | K6: 12 | L6: =K6/J6 -> 0.14457831 | P6: =L6/L7*P7 -> 0.1446721 | R6: 1843 | S6: =ISNUMBER(P6)*ISNUMBER(F6) -> 1
A7: 1844 | C7: 17.898163 | D7: 17.9 | F7: =C7 -> 17.898163 | H7: 1844 | I7: 0.2540867 | J7: 106 | K7: 13 | L7: =K7/J7 -> 0.12264151 | P7: =L7/L8*P8 -> 0.12272106 | R7: 1844 | S7: =ISNUMBER(P7)*ISNUMBER(F7) -> 1
A8: 1845 | C8: 17.898529 | D8: 17.9 | F8: =C8 -> 17.898529 | H8: 1845 | I8: 0.2720374 | J8: 106 | K8: 12 | L8: =K8/J8 -> 0.11320755 | P8: =L8/L9*P9 -> 0.11328098 | R8: 1845 | S8: =ISNUMBER(P8)*ISNUMBER(F8) -> 1
A9: 1846 | C9: 17.673256 | D9: 17.9 | F9: =C9 -> 17.673256 | H9: 1846 | I9: 0.2596588 | J9: 110 | K9: 14 | L9: =K9/J9 -> 0.12727273 | P9: =L9/L10*P10 -> 0.12735528 | R9: 1846 | S9: =ISNUMBER(P9)*ISNUMBER(F9) -> 1
A10: 1847 | C10: 15.606618 | D10: 14.5 | F10: =C10 -> 15.606618 | H10: 1847 | I10: 0.1590065 | J10: 157 | K10: 19 | L10: =K10/J10 -> 0.12101911 | P10: =L10/L11*P11 -> 0.12109761 | R10: 1847 | S10: =ISNUMBER(P10)*ISNUMBER(F10) -> 1
A11: 1848 | C11: 17.918877 | D11: 19.3 | F11: =C11 -> 17.918877 | H11: 1848 | I11: 0.1481267 | J11: 138 | K11: 15 | L11: =K11/J11 -> 0.10869565 | P11: =L11/L12*P12 -> 0.10876616 | R11: 1848 | S11: =ISNUMBER(P11)*ISNUMBER(F11) -> 1
A12: 1849 | C12: 17.984858 | D12: 18 | F12: =C12 -> 17.984858 | H12: 1849 | I12: 0.2112895 | J12: 140 | K12: 13 | L12: =K12/J12 -> 0.092857143 | P12: =L12/L13*P13 -> 0.092917376 | R12: 1849 | S12: =ISNUMBER(P12)*ISNUMBER(F12) -> 1
A13: 1850 | C13: 16.521094 | D13: 16.1 | F13: =C13 -> 16.521094 | H13: 1850 | I13: 0.1746777 | J13: 144 | K13: 18 | L13: =K13/J13 -> 0.125 | P13: =L13/L14*P14 -> 0.12508108 | R13: 1850 | S13: =ISNUMBER(P13)*ISNUMBER(F13) -> 1
A14: 1851 | C14: 15.711605 | D14: 15.7 | F14: =C14 -> 15.711605 | H14: 1851 | I14: 0.1341812 | J14: 189 | K14: 21 | L14: =K14/J14 -> 0.11111111 | P14: =L14/L15*P15 -> 0.11118319 | R14: 1851 | S14: =ISNUMBER(P14)*ISNUMBER(F14) -> 1
... A105: 1942 | C105: 7.7678621 | D105: 6.2 | F105: =C105 -> 7.7678621 | H105: 1942 | I105: 0.0004031 | J105: 8079 | K105: 1 | L105: =K105/J105 -> 0.0001237777 | P105: =L105/L106*P106 -> 0.00012385799 | R105: 1942 | S105: =ISNUMBER(P105)*ISNUMBER(F105) -> 1
A106: 1943 | C106: 6.879789 | D106: 7.15 | F106: =C106 -> 6.879789 | H106: 1943 | I106: 0.0001155 | J106: 12965 | K106: ---- | L106: =I106/I105*L105 -> 3.5465948e-05 | P106: =L106/L107*P107 -> 3.5488954e-05 | R106: 1943 | S106: =ISNUMBER(P106)*ISNUMBER(F106) -> 1
A107: 1944 | C107: 6.1819474 | D107: 5.51 | F107: =C107 -> 6.1819474 | H107: 1944 | I107: 0.0022574 | J107: 14259 | K107: 18 | L107: =K107/J107 -> 0.0012623606 | P107: =L107/L108*P108 -> 0.0012631795 | R107: 1944 | S107: =ISNUMBER(P107)*ISNUMBER(F107) -> 1
A108: 1945 | C108: 6.629607 | D108: 6.67 | F108: =C108 -> 6.629607 | H108: 1945 | I108: 0.0558839 | J108: 9806 | K108: 472 | L108: =K108/J108 -> 0.048133796 | P108: =L108/L109*P109 -> 0.048165018 | R108: 1945 | S108: =ISNUMBER(P108)*ISNUMBER(F108) -> 1
A109: 1946 | C109: 9.5099061 | D109: 10.94 | F109: =C109 -> 9.5099061 | H109: 1946 | I109: 0.0759998 | J109: 9738 | K109: 709 | L109: =K109/J109 -> 0.072807558 | P109: =L109/L110*P110 -> 0.072854786 | R109: 1946 | S109: =ISNUMBER(P109)*ISNUMBER(F109) -> 1
A110: 1947 | C110: 10.648788 | D110: 10.66 | F110: =C110 -> 10.648788 | H110: 1947 | I110: 0.0708339 | J110: 14430 | K110: 817 | L110: =K110/J110 -> 0.056618157 | P110: =L110/L111*P111 -> 0.056654883 | R110: 1947 | S110: =ISNUMBER(P110)*ISNUMBER(F110) -> 1
A111: 1948 | C111: 8.8101372 | D111: 8.3 | F111: =C111 -> 8.8101372 | H111: 1948 | I111: 0.0455879 | J111: 12653 | K111: 591 | L111: =K111/J111 -> 0.046708291 | P111: =L111/L112*P112 -> 0.046738589 | R111: 1948 | S111: =ISNUMBER(P111)*ISNUMBER(F111) -> 1
A112: 1949 | C112: 4.45153 | D112: 2.71 | F112: =C112 -> 4.45153 | H112: 1949 | I112: 0.0416194 | J112: 12051 | K112: 497 | L112: =K112/J112 -> 0.041241391 | P112: =L112/L113*P113 -> 0.041268143 | R112: 1949 | S112: =ISNUMBER(P112)*ISNUMBER(F112) -> 1
A113: 1950 | C113: 4.0353358 | D113: 4.84 | F113: =C113 -> 4.0353358 | H113: 1950 | I113: 0.0464457 | J113: 10275 | K113: 475 | L113: =K113/J113 -> 0.04622871 | P113: =L113/L114*P114 -> 0.046258697 | R113: 1950 | S113: =ISNUMBER(P113)*ISNUMBER(F113) -> 1
A114: 1951 | C114: 4.1226322 | D114: 3.89 | F114: =C114 -> 4.1226322 | H114: 1951 | I114: 0.0347561 | J114: 15032 | K114: 843 | L114: =K114/J114 -> 0.056080362 | P114: =L114/L115*P115 -> 0.056116739 | R114: 1951 | S114: =ISNUMBER(P114)*ISNUMBER(F114) -> 1
A115: 1952 | C115: 3.7924122 | D115: 3.72 | F115: =C115 -> 3.7924122 | H115: 1952 | I115: 0.0306648 | J115: 15201 | K115: 1013 | L115: =K115/J115 -> 0.066640353 | P115: =L115/L116*P116 -> 0.06668358 | R115: 1952 | S115: =ISNUMBER(P115)*ISNUMBER(F115) -> 1
A116: 1953 | C116: 4.136518 | D116: 4.35 | F116: =C116 -> 4.136518 | H116: 1953 | I116: 0.0251288 | J116: 15774 | K116: 1236 | L116: =K116/J116 -> 0.07835679 | P116: =L116/L117*P117 -> 0.078407617 | R116: 1953 | S116: =ISNUMBER(P116)*ISNUMBER(F116) -> 1
A117: 1954 | C117: 4.575444 | D117: 4.58 | F117: =C117 -> 4.575444 | H117: 1954 | I117: 0.0259133 | J117: 15110 | K117: 783 | L117: =K117/J117 -> 0.051819987 | P117: =L117/L118*P118 -> 0.051853601 | R117: 1954 | S117: =ISNUMBER(P117)*ISNUMBER(F117) -> 1
A118: 1955 | C118: 5.0101266 | D118: 5.29 | F118: =C118 -> 5.0101266 | H118: 1955 | I118: 0.0347646 | J118: 15547 | K118: 536 | L118: =K118/J118 -> 0.034476105 | P118: =L118/L119*P119 -> 0.034498468 | R118: 1955 | S118: =ISNUMBER(P118)*ISNUMBER(F118) -> 1
... A127: 1964 | C127: 6.7840956 | D127: 6.65 | F127: =C127 -> 6.7840956 | H127: 1964 | I127: 0.0373909 | J127: 26508 | K127: 990 | L127: =K127/J127 -> 0.037347216 | P127: =L127/L128*P128 -> 0.037371442 | R127: 1964 | S127: =ISNUMBER(P127)*ISNUMBER(F127) -> 1
A128: 1965 | C128: 6.1534547 | D128: 6.207079 | E128: =INDEX('OECD tau'!$AT$10:$BM$69,MATCH($A128,'OECD tau'!$AS$10:$AS$69,0),MATCH($A$1,'OECD tau'!$AT$8:$BM$8,0)) -> 6.0530018 | F128: =C128 -> 6.1534547 | H128: 1965 | I128: 0.0352557 | J128: 27470 | K128: 971 | L128: =K128/J128 -> 0.035347652 | P128: =L128/L129*P129 -> 0.035370581 | R128: 1965 | S128: =ISNUMBER(P128)*ISNUMBER(F128) -> 1
A129: 1966 | C129: 5.9151897 | D129: 5.501528 | E129: =INDEX('OECD tau'!$AT$10:$BM$69,MATCH($A129,'OECD tau'!$AS$10:$AS$69,0),MATCH($A$1,'OECD tau'!$AT$8:$BM$8,0)) -> 5.4070054 | F129: =C129 -> 5.9151897 | H129: 1966 | I129: 0.0325539 | J129: 30320 | K129: 1007 | L129: =K129/J129 -> 0.033212401 | P129: =L129/L130*P130 -> 0.033233945 | R129: 1966 | S129: =ISNUMBER(P129)*ISNUMBER(F129) -> 1
A130: 1967 | C130: 5.4342912 | D130: 5.181827 | E130: =INDEX('OECD tau'!$AT$10:$BM$69,MATCH($A130,'OECD tau'!$AS$10:$AS$69,0),MATCH($A$1,'OECD tau'!$AT$8:$BM$8,0)) -> 5.0923154 | F130: =C130 -> 5.4342912 | H130: 1967 | I130: 0.0314249 | J130: 31526 | K130: 1025 | L130: =K130/J130 -> 0.032512847 | P130: =L130/L131*P131 -> 0.032533937 | R130: 1967 | S130: =ISNUMBER(P130)*ISNUMBER(F130) -> 1
A131: 1968 | C131: 4.3517196 | D131: 3.983068 | E131: =INDEX('OECD tau'!$AT$10:$BM$69,MATCH($A131,'OECD tau'!$AS$10:$AS$69,0),MATCH($A$1,'OECD tau'!$AT$8:$BM$8,0)) -> 3.9181297 | F131: =C131 -> 4.3517196 | H131: 1968 | I131: 0.0304576 | J131: 34636 | K131: 1095 | L131: =K131/J131 -> 0.031614505 | P131: =L131/L132*P132 -> 0.031635012 | R131: 1968 | S131: =ISNUMBER(P131)*ISNUMBER(F131) -> 1
A132: 1969 | C132: 3.2879067 | D132: 2.911973 | E132: =INDEX('OECD tau'!$AT$10:$BM$69,MATCH($A132,'OECD tau'!$AS$10:$AS$69,0),MATCH($A$1,'OECD tau'!$AT$8:$BM$8,0)) -> 2.9396614 | F132: =C132 -> 3.2879067 | H132: 1969 | I132: 0.0304139 | J132: 38006 | K132: 1195 | L132: =K132/J132 -> 0.031442404 | P132: =L132/L133*P133 -> 0.031462799 | R132: 1969 | S132: =ISNUMBER(P132)*ISNUMBER(F132) -> 1
A133: 1970 | C133: 2.6771038 | D133: 2.633159 | E133: =INDEX('OECD tau'!$AT$10:$BM$69,MATCH($A133,'OECD tau'!$AS$10:$AS$69,0),MATCH($A$1,'OECD tau'!$AT$8:$BM$8,0)) -> 2.8079587 | F133: =C133 -> 2.6771038 | H133: 1970 | I133: 0.033348 | J133: 43224 | K133: 1483 | L133: =K133/J133 -> 0.034309643 | P133: =L133/L134*P134 -> 0.034331898 | R133: 1970 | S133: =ISNUMBER(P133)*ISNUMBER(F133) -> 1
